2019-06-24 17:46:41,358  WARNING  42380  C:\Users\MMCCOW~1\Envs\DJANGO~1\lib\site-packages\django\utils\log.py  log_response  228  Not Found: /favicon.ico  
2019-06-24 17:53:57,627  ERROR  44324  C:\Users\MMCCOW~1\Envs\DJANGO~1\lib\site-packages\django\utils\log.py  log_response  228  Internal Server Error: /records/add/instrument-setting/  
Traceback (most recent call last):
  File "C:\Users\MMCCOW~1\Envs\DJANGO~1\lib\site-packages\django\core\handlers\exception.py", line 34, in inner
    response = get_response(request)
  File "C:\Users\MMCCOW~1\Envs\DJANGO~1\lib\site-packages\django\core\handlers\base.py", line 126, in _get_response
    response = self.process_exception_by_middleware(e, request)
  File "C:\Users\MMCCOW~1\Envs\DJANGO~1\lib\site-packages\django\core\handlers\base.py", line 124, in _get_response
    response = wrapped_callback(request, *callback_args, **callback_kwargs)
  File "C:\Users\M McCown\SCS\DataMan\Records\views.py", line 1012, in add_instrument_setting
    new_inst = form.save()
  File "C:\Users\MMCCOW~1\Envs\DJANGO~1\lib\site-packages\django\forms\models.py", line 458, in save
    self.instance.save()
  File "C:\Users\MMCCOW~1\Envs\DJANGO~1\lib\site-packages\django\db\models\base.py", line 718, in save
    force_update=force_update, update_fields=update_fields)
  File "C:\Users\MMCCOW~1\Envs\DJANGO~1\lib\site-packages\django\db\models\base.py", line 747, in save_base
    self._save_parents(cls, using, update_fields)
  File "C:\Users\MMCCOW~1\Envs\DJANGO~1\lib\site-packages\django\db\models\base.py", line 772, in _save_parents
    self._save_table(cls=parent, using=using, update_fields=update_fields)
  File "C:\Users\MMCCOW~1\Envs\DJANGO~1\lib\site-packages\django\db\models\base.py", line 809, in _save_table
    for f in non_pks]
  File "C:\Users\MMCCOW~1\Envs\DJANGO~1\lib\site-packages\django\db\models\base.py", line 809, in <listcomp>
    for f in non_pks]
  File "C:\Users\MMCCOW~1\Envs\DJANGO~1\lib\site-packages\django\db\models\fields\files.py", line 288, in pre_save
    file.save(file.name, file.file, save=False)
  File "C:\Users\MMCCOW~1\Envs\DJANGO~1\lib\site-packages\django\db\models\fields\files.py", line 87, in save
    self.name = self.storage.save(name, content, max_length=self.field.max_length)
  File "C:\Users\MMCCOW~1\Envs\DJANGO~1\lib\site-packages\django\core\files\storage.py", line 48, in save
    name = self.get_available_name(name, max_length=max_length)
TypeError: get_available_name() got an unexpected keyword argument 'max_length'
2019-06-25 08:55:42,376  WARNING  36916  C:\Users\MMCCOW~1\Envs\DJANGO~1\lib\site-packages\django\utils\log.py  log_response  228  Not Found: /favicon.ico  
2019-06-25 08:56:35,530  ERROR  26708  C:\Users\MMCCOW~1\Envs\DJANGO~1\lib\site-packages\django\utils\log.py  log_response  228  Internal Server Error: /records/add/instrument-setting/  
Traceback (most recent call last):
  File "C:\Users\MMCCOW~1\Envs\DJANGO~1\lib\site-packages\django\core\handlers\exception.py", line 34, in inner
    response = get_response(request)
  File "C:\Users\MMCCOW~1\Envs\DJANGO~1\lib\site-packages\django\core\handlers\base.py", line 126, in _get_response
    response = self.process_exception_by_middleware(e, request)
  File "C:\Users\MMCCOW~1\Envs\DJANGO~1\lib\site-packages\django\core\handlers\base.py", line 124, in _get_response
    response = wrapped_callback(request, *callback_args, **callback_kwargs)
  File "C:\Users\M McCown\SCS\DataMan\Records\views.py", line 1012, in add_instrument_setting
    new_inst = form.save()
  File "C:\Users\MMCCOW~1\Envs\DJANGO~1\lib\site-packages\django\forms\models.py", line 458, in save
    self.instance.save()
  File "C:\Users\MMCCOW~1\Envs\DJANGO~1\lib\site-packages\django\db\models\base.py", line 718, in save
    force_update=force_update, update_fields=update_fields)
  File "C:\Users\MMCCOW~1\Envs\DJANGO~1\lib\site-packages\django\db\models\base.py", line 747, in save_base
    self._save_parents(cls, using, update_fields)
  File "C:\Users\MMCCOW~1\Envs\DJANGO~1\lib\site-packages\django\db\models\base.py", line 772, in _save_parents
    self._save_table(cls=parent, using=using, update_fields=update_fields)
  File "C:\Users\MMCCOW~1\Envs\DJANGO~1\lib\site-packages\django\db\models\base.py", line 809, in _save_table
    for f in non_pks]
  File "C:\Users\MMCCOW~1\Envs\DJANGO~1\lib\site-packages\django\db\models\base.py", line 809, in <listcomp>
    for f in non_pks]
  File "C:\Users\MMCCOW~1\Envs\DJANGO~1\lib\site-packages\django\db\models\fields\files.py", line 288, in pre_save
    file.save(file.name, file.file, save=False)
  File "C:\Users\MMCCOW~1\Envs\DJANGO~1\lib\site-packages\django\db\models\fields\files.py", line 87, in save
    self.name = self.storage.save(name, content, max_length=self.field.max_length)
  File "C:\Users\MMCCOW~1\Envs\DJANGO~1\lib\site-packages\django\core\files\storage.py", line 48, in save
    name = self.get_available_name(name, max_length=max_length)
  File "C:\Users\M McCown\SCS\DataMan\Records\models.py", line 301, in get_available_name
    old_copy = self.get(name)
AttributeError: 'CheckDuplicateStorage' object has no attribute 'get'
2019-06-25 08:57:01,316  WARNING  43672  C:\Users\MMCCOW~1\Envs\DJANGO~1\lib\site-packages\django\utils\log.py  log_response  228  Not Found: /favicon.ico  
2019-06-25 08:57:25,100  ERROR  50116  C:\Users\MMCCOW~1\Envs\DJANGO~1\lib\site-packages\django\utils\log.py  log_response  228  Internal Server Error: /records/add/instrument-setting/  
Traceback (most recent call last):
  File "C:\Users\MMCCOW~1\Envs\DJANGO~1\lib\site-packages\django\core\handlers\exception.py", line 34, in inner
    response = get_response(request)
  File "C:\Users\MMCCOW~1\Envs\DJANGO~1\lib\site-packages\django\core\handlers\base.py", line 126, in _get_response
    response = self.process_exception_by_middleware(e, request)
  File "C:\Users\MMCCOW~1\Envs\DJANGO~1\lib\site-packages\django\core\handlers\base.py", line 124, in _get_response
    response = wrapped_callback(request, *callback_args, **callback_kwargs)
  File "C:\Users\M McCown\SCS\DataMan\Records\views.py", line 1012, in add_instrument_setting
    new_inst = form.save()
  File "C:\Users\MMCCOW~1\Envs\DJANGO~1\lib\site-packages\django\forms\models.py", line 458, in save
    self.instance.save()
  File "C:\Users\MMCCOW~1\Envs\DJANGO~1\lib\site-packages\django\db\models\base.py", line 718, in save
    force_update=force_update, update_fields=update_fields)
  File "C:\Users\MMCCOW~1\Envs\DJANGO~1\lib\site-packages\django\db\models\base.py", line 747, in save_base
    self._save_parents(cls, using, update_fields)
  File "C:\Users\MMCCOW~1\Envs\DJANGO~1\lib\site-packages\django\db\models\base.py", line 772, in _save_parents
    self._save_table(cls=parent, using=using, update_fields=update_fields)
  File "C:\Users\MMCCOW~1\Envs\DJANGO~1\lib\site-packages\django\db\models\base.py", line 809, in _save_table
    for f in non_pks]
  File "C:\Users\MMCCOW~1\Envs\DJANGO~1\lib\site-packages\django\db\models\base.py", line 809, in <listcomp>
    for f in non_pks]
  File "C:\Users\MMCCOW~1\Envs\DJANGO~1\lib\site-packages\django\db\models\fields\files.py", line 288, in pre_save
    file.save(file.name, file.file, save=False)
  File "C:\Users\MMCCOW~1\Envs\DJANGO~1\lib\site-packages\django\db\models\fields\files.py", line 87, in save
    self.name = self.storage.save(name, content, max_length=self.field.max_length)
  File "C:\Users\MMCCOW~1\Envs\DJANGO~1\lib\site-packages\django\core\files\storage.py", line 48, in save
    name = self.get_available_name(name, max_length=max_length)
  File "C:\Users\M McCown\SCS\DataMan\Records\models.py", line 301, in get_available_name
    old_copy = self.objects#.get(name)
AttributeError: 'CheckDuplicateStorage' object has no attribute 'objects'
2019-06-25 08:57:37,344  ERROR  17504  C:\Users\MMCCOW~1\Envs\DJANGO~1\lib\site-packages\django\utils\log.py  log_response  228  Internal Server Error: /records/add/instrument-setting/  
Traceback (most recent call last):
  File "C:\Users\MMCCOW~1\Envs\DJANGO~1\lib\site-packages\django\core\handlers\exception.py", line 34, in inner
    response = get_response(request)
  File "C:\Users\MMCCOW~1\Envs\DJANGO~1\lib\site-packages\django\core\handlers\base.py", line 126, in _get_response
    response = self.process_exception_by_middleware(e, request)
  File "C:\Users\MMCCOW~1\Envs\DJANGO~1\lib\site-packages\django\core\handlers\base.py", line 124, in _get_response
    response = wrapped_callback(request, *callback_args, **callback_kwargs)
  File "C:\Users\M McCown\SCS\DataMan\Records\views.py", line 1012, in add_instrument_setting
    new_inst = form.save()
  File "C:\Users\MMCCOW~1\Envs\DJANGO~1\lib\site-packages\django\forms\models.py", line 458, in save
    self.instance.save()
  File "C:\Users\MMCCOW~1\Envs\DJANGO~1\lib\site-packages\django\db\models\base.py", line 718, in save
    force_update=force_update, update_fields=update_fields)
  File "C:\Users\MMCCOW~1\Envs\DJANGO~1\lib\site-packages\django\db\models\base.py", line 747, in save_base
    self._save_parents(cls, using, update_fields)
  File "C:\Users\MMCCOW~1\Envs\DJANGO~1\lib\site-packages\django\db\models\base.py", line 772, in _save_parents
    self._save_table(cls=parent, using=using, update_fields=update_fields)
  File "C:\Users\MMCCOW~1\Envs\DJANGO~1\lib\site-packages\django\db\models\base.py", line 809, in _save_table
    for f in non_pks]
  File "C:\Users\MMCCOW~1\Envs\DJANGO~1\lib\site-packages\django\db\models\base.py", line 809, in <listcomp>
    for f in non_pks]
  File "C:\Users\MMCCOW~1\Envs\DJANGO~1\lib\site-packages\django\db\models\fields\files.py", line 288, in pre_save
    file.save(file.name, file.file, save=False)
  File "C:\Users\MMCCOW~1\Envs\DJANGO~1\lib\site-packages\django\db\models\fields\files.py", line 87, in save
    self.name = self.storage.save(name, content, max_length=self.field.max_length)
  File "C:\Users\MMCCOW~1\Envs\DJANGO~1\lib\site-packages\django\core\files\storage.py", line 48, in save
    name = self.get_available_name(name, max_length=max_length)
  File "C:\Users\M McCown\SCS\DataMan\Records\models.py", line 301, in get_available_name
    old_copy = self.Objects#.get(name)
AttributeError: 'CheckDuplicateStorage' object has no attribute 'Objects'
2019-06-25 08:57:37,473  WARNING  17504  C:\Users\MMCCOW~1\Envs\DJANGO~1\lib\site-packages\django\utils\log.py  log_response  228  Not Found: /favicon.ico  
2019-06-25 08:59:54,264  WARNING  49320  C:\Users\MMCCOW~1\Envs\DJANGO~1\lib\site-packages\django\utils\log.py  log_response  228  Not Found: /favicon.ico  
2019-06-25 09:01:55,361  ERROR  27756  C:\Users\MMCCOW~1\Envs\DJANGO~1\lib\site-packages\django\utils\log.py  log_response  228  Internal Server Error: /records/add/instrument-setting/  
Traceback (most recent call last):
  File "C:\Users\MMCCOW~1\Envs\DJANGO~1\lib\site-packages\django\core\handlers\exception.py", line 34, in inner
    response = get_response(request)
  File "C:\Users\MMCCOW~1\Envs\DJANGO~1\lib\site-packages\django\core\handlers\base.py", line 126, in _get_response
    response = self.process_exception_by_middleware(e, request)
  File "C:\Users\MMCCOW~1\Envs\DJANGO~1\lib\site-packages\django\core\handlers\base.py", line 124, in _get_response
    response = wrapped_callback(request, *callback_args, **callback_kwargs)
  File "C:\Users\M McCown\SCS\DataMan\Records\views.py", line 1012, in add_instrument_setting
    new_inst = form.save()
  File "C:\Users\MMCCOW~1\Envs\DJANGO~1\lib\site-packages\django\forms\models.py", line 458, in save
    self.instance.save()
  File "C:\Users\MMCCOW~1\Envs\DJANGO~1\lib\site-packages\django\db\models\base.py", line 718, in save
    force_update=force_update, update_fields=update_fields)
  File "C:\Users\MMCCOW~1\Envs\DJANGO~1\lib\site-packages\django\db\models\base.py", line 747, in save_base
    self._save_parents(cls, using, update_fields)
  File "C:\Users\MMCCOW~1\Envs\DJANGO~1\lib\site-packages\django\db\models\base.py", line 772, in _save_parents
    self._save_table(cls=parent, using=using, update_fields=update_fields)
  File "C:\Users\MMCCOW~1\Envs\DJANGO~1\lib\site-packages\django\db\models\base.py", line 809, in _save_table
    for f in non_pks]
  File "C:\Users\MMCCOW~1\Envs\DJANGO~1\lib\site-packages\django\db\models\base.py", line 809, in <listcomp>
    for f in non_pks]
  File "C:\Users\MMCCOW~1\Envs\DJANGO~1\lib\site-packages\django\db\models\fields\files.py", line 288, in pre_save
    file.save(file.name, file.file, save=False)
  File "C:\Users\MMCCOW~1\Envs\DJANGO~1\lib\site-packages\django\db\models\fields\files.py", line 87, in save
    self.name = self.storage.save(name, content, max_length=self.field.max_length)
  File "C:\Users\MMCCOW~1\Envs\DJANGO~1\lib\site-packages\django\core\files\storage.py", line 48, in save
    name = self.get_available_name(name, max_length=max_length)
  File "C:\Users\M McCown\SCS\DataMan\Records\models.py", line 304, in get_available_name
    print(old_copy.size())
TypeError: 'int' object is not callable
2019-06-25 09:02:18,788  WARNING  41532  C:\Users\MMCCOW~1\Envs\DJANGO~1\lib\site-packages\django\utils\log.py  log_response  228  Not Found: /favicon.ico  
2019-06-25 09:10:13,651  WARNING  43156  C:\Users\MMCCOW~1\Envs\DJANGO~1\lib\site-packages\django\utils\log.py  log_response  228  Not Found: /favicon.ico  
2019-06-25 09:15:31,029  WARNING  49648  C:\Users\MMCCOW~1\Envs\DJANGO~1\lib\site-packages\django\utils\log.py  log_response  228  Not Found: /favicon.ico  
2019-06-25 09:15:47,787  WARNING  49648  C:\Users\MMCCOW~1\Envs\DJANGO~1\lib\site-packages\django\utils\log.py  log_response  228  Not Found: /favicon.ico  
2019-06-25 09:32:41,124  WARNING  22540  C:\Users\MMCCOW~1\Envs\DJANGO~1\lib\site-packages\django\utils\log.py  log_response  228  Not Found: /favicon.ico  
2019-06-25 09:34:15,790  WARNING  11580  C:\Users\MMCCOW~1\Envs\DJANGO~1\lib\site-packages\django\utils\log.py  log_response  228  Not Found: /favicon.ico  
2019-06-25 09:52:55,696  WARNING  32888  C:\Users\MMCCOW~1\Envs\DJANGO~1\lib\site-packages\django\utils\log.py  log_response  228  Not Found: /favicon.ico  
2019-06-25 09:56:46,772  WARNING  40036  C:\Users\MMCCOW~1\Envs\DJANGO~1\lib\site-packages\django\utils\log.py  log_response  228  Not Found: /favicon.ico  
2019-06-25 10:59:07,279  ERROR  21836  C:\Users\MMCCOW~1\Envs\DJANGO~1\lib\site-packages\django\utils\log.py  log_response  228  Internal Server Error: /records/add/instrument-setting/  
Traceback (most recent call last):
  File "C:\Users\MMCCOW~1\Envs\DJANGO~1\lib\site-packages\django\core\handlers\exception.py", line 34, in inner
    response = get_response(request)
  File "C:\Users\MMCCOW~1\Envs\DJANGO~1\lib\site-packages\django\core\handlers\base.py", line 126, in _get_response
    response = self.process_exception_by_middleware(e, request)
  File "C:\Users\MMCCOW~1\Envs\DJANGO~1\lib\site-packages\django\core\handlers\base.py", line 124, in _get_response
    response = wrapped_callback(request, *callback_args, **callback_kwargs)
  File "C:\Users\M McCown\SCS\DataMan\Records\views.py", line 1015, in add_instrument_setting
    new_inst = form.save()
  File "C:\Users\MMCCOW~1\Envs\DJANGO~1\lib\site-packages\django\forms\models.py", line 458, in save
    self.instance.save()
  File "C:\Users\MMCCOW~1\Envs\DJANGO~1\lib\site-packages\django\db\models\base.py", line 718, in save
    force_update=force_update, update_fields=update_fields)
  File "C:\Users\MMCCOW~1\Envs\DJANGO~1\lib\site-packages\django\db\models\base.py", line 747, in save_base
    self._save_parents(cls, using, update_fields)
  File "C:\Users\MMCCOW~1\Envs\DJANGO~1\lib\site-packages\django\db\models\base.py", line 772, in _save_parents
    self._save_table(cls=parent, using=using, update_fields=update_fields)
  File "C:\Users\MMCCOW~1\Envs\DJANGO~1\lib\site-packages\django\db\models\base.py", line 809, in _save_table
    for f in non_pks]
  File "C:\Users\MMCCOW~1\Envs\DJANGO~1\lib\site-packages\django\db\models\base.py", line 809, in <listcomp>
    for f in non_pks]
  File "C:\Users\MMCCOW~1\Envs\DJANGO~1\lib\site-packages\django\db\models\fields\files.py", line 288, in pre_save
    file.save(file.name, file.file, save=False)
  File "C:\Users\MMCCOW~1\Envs\DJANGO~1\lib\site-packages\django\db\models\fields\files.py", line 87, in save
    self.name = self.storage.save(name, content, max_length=self.field.max_length)
  File "C:\Users\M McCown\SCS\DataMan\Records\models.py", line 313, in save
    tk.withdraw()
AttributeError: module 'tkinter' has no attribute 'withdraw'
2019-06-25 11:11:34,721  ERROR  46996  C:\Users\MMCCOW~1\Envs\DJANGO~1\lib\site-packages\django\utils\log.py  log_response  228  Internal Server Error: /records/add/instrument-setting/  
Traceback (most recent call last):
  File "C:\Users\MMCCOW~1\Envs\DJANGO~1\lib\site-packages\django\core\handlers\exception.py", line 34, in inner
    response = get_response(request)
  File "C:\Users\MMCCOW~1\Envs\DJANGO~1\lib\site-packages\django\core\handlers\base.py", line 126, in _get_response
    response = self.process_exception_by_middleware(e, request)
  File "C:\Users\MMCCOW~1\Envs\DJANGO~1\lib\site-packages\django\core\handlers\base.py", line 124, in _get_response
    response = wrapped_callback(request, *callback_args, **callback_kwargs)
  File "C:\Users\M McCown\SCS\DataMan\Records\views.py", line 1015, in add_instrument_setting
    new_inst = form.save()
  File "C:\Users\MMCCOW~1\Envs\DJANGO~1\lib\site-packages\django\forms\models.py", line 458, in save
    self.instance.save()
  File "C:\Users\MMCCOW~1\Envs\DJANGO~1\lib\site-packages\django\db\models\base.py", line 718, in save
    force_update=force_update, update_fields=update_fields)
  File "C:\Users\MMCCOW~1\Envs\DJANGO~1\lib\site-packages\django\db\models\base.py", line 747, in save_base
    self._save_parents(cls, using, update_fields)
  File "C:\Users\MMCCOW~1\Envs\DJANGO~1\lib\site-packages\django\db\models\base.py", line 772, in _save_parents
    self._save_table(cls=parent, using=using, update_fields=update_fields)
  File "C:\Users\MMCCOW~1\Envs\DJANGO~1\lib\site-packages\django\db\models\base.py", line 809, in _save_table
    for f in non_pks]
  File "C:\Users\MMCCOW~1\Envs\DJANGO~1\lib\site-packages\django\db\models\base.py", line 809, in <listcomp>
    for f in non_pks]
  File "C:\Users\MMCCOW~1\Envs\DJANGO~1\lib\site-packages\django\db\models\fields\files.py", line 288, in pre_save
    file.save(file.name, file.file, save=False)
  File "C:\Users\MMCCOW~1\Envs\DJANGO~1\lib\site-packages\django\db\models\fields\files.py", line 87, in save
    self.name = self.storage.save(name, content, max_length=self.field.max_length)
  File "C:\Users\M McCown\SCS\DataMan\Records\models.py", line 314, in save
    tk.messagebox.showinfo('Duplicate File', "This file is already in our system and will not be uploaded again.")
  File "c:\anaconda3\Lib\tkinter\messagebox.py", line 83, in showinfo
    return _show(title, message, INFO, OK, **options)
  File "c:\anaconda3\Lib\tkinter\messagebox.py", line 72, in _show
    res = Message(**options).show()
  File "c:\anaconda3\Lib\tkinter\commondialog.py", line 39, in show
    w = Frame(self.master)
  File "c:\anaconda3\Lib\tkinter\__init__.py", line 2744, in __init__
    Widget.__init__(self, master, 'frame', cnf, {}, extra)
  File "c:\anaconda3\Lib\tkinter\__init__.py", line 2299, in __init__
    (widgetName, self._w) + extra + self._options(cnf))
RuntimeError: main thread is not in main loop
2019-06-25 12:15:43,378  WARNING  45240  C:\Users\MMCCOW~1\Envs\DJANGO~1\lib\site-packages\django\utils\log.py  log_response  228  Not Found: /favicon.ico  
2019-06-26 15:16:18,525  WARNING  6436  C:\Users\MMCCOW~1\Envs\DJANGO~1\lib\site-packages\django\utils\log.py  log_response  228  Not Found: /favicon.ico  
2019-06-26 15:29:11,346  WARNING  6436  C:\Users\MMCCOW~1\Envs\DJANGO~1\lib\site-packages\django\utils\log.py  log_response  228  Not Found: /favicon.ico  
2019-06-26 15:34:17,191  ERROR  6436  C:\Users\MMCCOW~1\Envs\DJANGO~1\lib\site-packages\django\utils\log.py  log_response  228  Internal Server Error: /records/individuals/23/  
Traceback (most recent call last):
  File "C:\Users\MMCCOW~1\Envs\DJANGO~1\lib\site-packages\django\template\base.py", line 766, in __init__
    self.literal = float(var)
ValueError: could not convert string to float: 'individual._healthStatus'

During handling of the above exception, another exception occurred:

Traceback (most recent call last):
  File "C:\Users\MMCCOW~1\Envs\DJANGO~1\lib\site-packages\django\template\base.py", line 782, in __init__
    self.literal = mark_safe(unescape_string_literal(var))
  File "C:\Users\MMCCOW~1\Envs\DJANGO~1\lib\site-packages\django\utils\functional.py", line 195, in wrapper
    return func(*args, **kwargs)
  File "C:\Users\MMCCOW~1\Envs\DJANGO~1\lib\site-packages\django\utils\text.py", line 397, in unescape_string_literal
    raise ValueError("Not a string literal: %r" % s)
ValueError: Not a string literal: 'individual._healthStatus'

During handling of the above exception, another exception occurred:

Traceback (most recent call last):
  File "C:\Users\MMCCOW~1\Envs\DJANGO~1\lib\site-packages\django\core\handlers\exception.py", line 34, in inner
    response = get_response(request)
  File "C:\Users\MMCCOW~1\Envs\DJANGO~1\lib\site-packages\django\core\handlers\base.py", line 156, in _get_response
    response = self.process_exception_by_middleware(e, request)
  File "C:\Users\MMCCOW~1\Envs\DJANGO~1\lib\site-packages\django\core\handlers\base.py", line 154, in _get_response
    response = response.render()
  File "C:\Users\MMCCOW~1\Envs\DJANGO~1\lib\site-packages\django\template\response.py", line 106, in render
    self.content = self.rendered_content
  File "C:\Users\MMCCOW~1\Envs\DJANGO~1\lib\site-packages\django\template\response.py", line 81, in rendered_content
    template = self.resolve_template(self.template_name)
  File "C:\Users\MMCCOW~1\Envs\DJANGO~1\lib\site-packages\django\template\response.py", line 63, in resolve_template
    return select_template(template, using=self.using)
  File "C:\Users\MMCCOW~1\Envs\DJANGO~1\lib\site-packages\django\template\loader.py", line 42, in select_template
    return engine.get_template(template_name)
  File "C:\Users\MMCCOW~1\Envs\DJANGO~1\lib\site-packages\django\template\backends\django.py", line 34, in get_template
    return Template(self.engine.get_template(template_name), self)
  File "C:\Users\MMCCOW~1\Envs\DJANGO~1\lib\site-packages\django\template\engine.py", line 144, in get_template
    template, origin = self.find_template(template_name)
  File "C:\Users\MMCCOW~1\Envs\DJANGO~1\lib\site-packages\django\template\engine.py", line 126, in find_template
    template = loader.get_template(name, skip=skip)
  File "C:\Users\MMCCOW~1\Envs\DJANGO~1\lib\site-packages\django\template\loaders\base.py", line 30, in get_template
    contents, origin, origin.template_name, self.engine,
  File "C:\Users\MMCCOW~1\Envs\DJANGO~1\lib\site-packages\django\template\base.py", line 156, in __init__
    self.nodelist = self.compile_nodelist()
  File "C:\Users\MMCCOW~1\Envs\DJANGO~1\lib\site-packages\django\template\base.py", line 194, in compile_nodelist
    return parser.parse()
  File "C:\Users\MMCCOW~1\Envs\DJANGO~1\lib\site-packages\django\template\base.py", line 478, in parse
    raise self.error(token, e)
  File "C:\Users\MMCCOW~1\Envs\DJANGO~1\lib\site-packages\django\template\base.py", line 476, in parse
    compiled_result = compile_func(self, token)
  File "C:\Users\MMCCOW~1\Envs\DJANGO~1\lib\site-packages\django\template\loader_tags.py", line 266, in do_extends
    nodelist = parser.parse()
  File "C:\Users\MMCCOW~1\Envs\DJANGO~1\lib\site-packages\django\template\base.py", line 478, in parse
    raise self.error(token, e)
  File "C:\Users\MMCCOW~1\Envs\DJANGO~1\lib\site-packages\django\template\base.py", line 476, in parse
    compiled_result = compile_func(self, token)
  File "C:\Users\MMCCOW~1\Envs\DJANGO~1\lib\site-packages\django\template\loader_tags.py", line 209, in do_block
    nodelist = parser.parse(('endblock',))
  File "C:\Users\MMCCOW~1\Envs\DJANGO~1\lib\site-packages\django\template\base.py", line 449, in parse
    raise self.error(token, e)
  File "C:\Users\MMCCOW~1\Envs\DJANGO~1\lib\site-packages\django\template\base.py", line 447, in parse
    filter_expression = self.compile_filter(token.contents)
  File "C:\Users\MMCCOW~1\Envs\DJANGO~1\lib\site-packages\django\template\base.py", line 563, in compile_filter
    return FilterExpression(token, self)
  File "C:\Users\MMCCOW~1\Envs\DJANGO~1\lib\site-packages\django\template\base.py", line 648, in __init__
    var_obj = Variable(var)
  File "C:\Users\MMCCOW~1\Envs\DJANGO~1\lib\site-packages\django\template\base.py", line 789, in __init__
    var)
django.template.exceptions.TemplateSyntaxError: Variables and attributes may not begin with underscores: 'individual._healthStatus'
2019-06-26 15:34:17,473  WARNING  6436  C:\Users\MMCCOW~1\Envs\DJANGO~1\lib\site-packages\django\utils\log.py  log_response  228  Not Found: /favicon.ico  
2019-06-26 15:34:23,869  WARNING  6436  C:\Users\MMCCOW~1\Envs\DJANGO~1\lib\site-packages\django\utils\log.py  log_response  228  Not Found: /favicon.ico  
2019-06-26 15:35:29,223  WARNING  14880  C:\Users\MMCCOW~1\Envs\DJANGO~1\lib\site-packages\django\utils\log.py  log_response  228  Not Found: /favicon.ico  
2019-06-26 15:36:12,991  WARNING  1228  C:\Users\MMCCOW~1\Envs\DJANGO~1\lib\site-packages\django\utils\log.py  log_response  228  Not Found: /favicon.ico  
2019-06-26 15:38:05,827  ERROR  47252  C:\Users\MMCCOW~1\Envs\DJANGO~1\lib\site-packages\django\utils\log.py  log_response  228  Internal Server Error: /records/samples/  
Traceback (most recent call last):
  File "C:\Users\MMCCOW~1\Envs\DJANGO~1\lib\site-packages\django_tables2\utils.py", line 344, in resolve
    current = current[bit]
TypeError: 'ManyRelatedManager' object is not subscriptable

During handling of the above exception, another exception occurred:

Traceback (most recent call last):
  File "C:\Users\MMCCOW~1\Envs\DJANGO~1\lib\site-packages\django_tables2\utils.py", line 347, in resolve
    current = getattr(current, bit)
AttributeError: 'ManyRelatedManager' object has no attribute 'pk'

During handling of the above exception, another exception occurred:

Traceback (most recent call last):
  File "C:\Users\MMCCOW~1\Envs\DJANGO~1\lib\site-packages\django_tables2\utils.py", line 350, in resolve
    current = current[int(bit)]
ValueError: invalid literal for int() with base 10: 'pk'

During handling of the above exception, another exception occurred:

Traceback (most recent call last):
  File "C:\Users\MMCCOW~1\Envs\DJANGO~1\lib\site-packages\django\core\handlers\exception.py", line 34, in inner
    response = get_response(request)
  File "C:\Users\MMCCOW~1\Envs\DJANGO~1\lib\site-packages\django\core\handlers\base.py", line 156, in _get_response
    response = self.process_exception_by_middleware(e, request)
  File "C:\Users\MMCCOW~1\Envs\DJANGO~1\lib\site-packages\django\core\handlers\base.py", line 154, in _get_response
    response = response.render()
  File "C:\Users\MMCCOW~1\Envs\DJANGO~1\lib\site-packages\django\template\response.py", line 106, in render
    self.content = self.rendered_content
  File "C:\Users\MMCCOW~1\Envs\DJANGO~1\lib\site-packages\django\template\response.py", line 83, in rendered_content
    content = template.render(context, self._request)
  File "C:\Users\MMCCOW~1\Envs\DJANGO~1\lib\site-packages\django\template\backends\django.py", line 61, in render
    return self.template.render(context)
  File "C:\Users\MMCCOW~1\Envs\DJANGO~1\lib\site-packages\django\template\base.py", line 171, in render
    return self._render(context)
  File "C:\Users\MMCCOW~1\Envs\DJANGO~1\lib\site-packages\django\template\base.py", line 163, in _render
    return self.nodelist.render(context)
  File "C:\Users\MMCCOW~1\Envs\DJANGO~1\lib\site-packages\django\template\base.py", line 937, in render
    bit = node.render_annotated(context)
  File "C:\Users\MMCCOW~1\Envs\DJANGO~1\lib\site-packages\django\template\base.py", line 904, in render_annotated
    return self.render(context)
  File "C:\Users\MMCCOW~1\Envs\DJANGO~1\lib\site-packages\django\template\loader_tags.py", line 150, in render
    return compiled_parent._render(context)
  File "C:\Users\MMCCOW~1\Envs\DJANGO~1\lib\site-packages\django\template\base.py", line 163, in _render
    return self.nodelist.render(context)
  File "C:\Users\MMCCOW~1\Envs\DJANGO~1\lib\site-packages\django\template\base.py", line 937, in render
    bit = node.render_annotated(context)
  File "C:\Users\MMCCOW~1\Envs\DJANGO~1\lib\site-packages\django\template\base.py", line 904, in render_annotated
    return self.render(context)
  File "C:\Users\MMCCOW~1\Envs\DJANGO~1\lib\site-packages\django\template\loader_tags.py", line 150, in render
    return compiled_parent._render(context)
  File "C:\Users\MMCCOW~1\Envs\DJANGO~1\lib\site-packages\django\template\base.py", line 163, in _render
    return self.nodelist.render(context)
  File "C:\Users\MMCCOW~1\Envs\DJANGO~1\lib\site-packages\django\template\base.py", line 937, in render
    bit = node.render_annotated(context)
  File "C:\Users\MMCCOW~1\Envs\DJANGO~1\lib\site-packages\django\template\base.py", line 904, in render_annotated
    return self.render(context)
  File "C:\Users\MMCCOW~1\Envs\DJANGO~1\lib\site-packages\django\template\loader_tags.py", line 62, in render
    result = block.nodelist.render(context)
  File "C:\Users\MMCCOW~1\Envs\DJANGO~1\lib\site-packages\django\template\base.py", line 937, in render
    bit = node.render_annotated(context)
  File "C:\Users\MMCCOW~1\Envs\DJANGO~1\lib\site-packages\django\template\base.py", line 904, in render_annotated
    return self.render(context)
  File "C:\Users\MMCCOW~1\Envs\DJANGO~1\lib\site-packages\django_tables2\templatetags\django_tables2.py", line 170, in render
    return template.render(context={"table": table}, request=request)
  File "C:\Users\MMCCOW~1\Envs\DJANGO~1\lib\site-packages\django\template\backends\django.py", line 61, in render
    return self.template.render(context)
  File "C:\Users\MMCCOW~1\Envs\DJANGO~1\lib\site-packages\django\template\base.py", line 171, in render
    return self._render(context)
  File "C:\Users\MMCCOW~1\Envs\DJANGO~1\lib\site-packages\django\template\base.py", line 163, in _render
    return self.nodelist.render(context)
  File "C:\Users\MMCCOW~1\Envs\DJANGO~1\lib\site-packages\django\template\base.py", line 937, in render
    bit = node.render_annotated(context)
  File "C:\Users\MMCCOW~1\Envs\DJANGO~1\lib\site-packages\django\template\base.py", line 904, in render_annotated
    return self.render(context)
  File "C:\Users\MMCCOW~1\Envs\DJANGO~1\lib\site-packages\django\template\loader_tags.py", line 53, in render
    result = self.nodelist.render(context)
  File "C:\Users\MMCCOW~1\Envs\DJANGO~1\lib\site-packages\django\template\base.py", line 937, in render
    bit = node.render_annotated(context)
  File "C:\Users\MMCCOW~1\Envs\DJANGO~1\lib\site-packages\django\template\base.py", line 904, in render_annotated
    return self.render(context)
  File "C:\Users\MMCCOW~1\Envs\DJANGO~1\lib\site-packages\django\template\loader_tags.py", line 53, in render
    result = self.nodelist.render(context)
  File "C:\Users\MMCCOW~1\Envs\DJANGO~1\lib\site-packages\django\template\base.py", line 937, in render
    bit = node.render_annotated(context)
  File "C:\Users\MMCCOW~1\Envs\DJANGO~1\lib\site-packages\django\template\base.py", line 904, in render_annotated
    return self.render(context)
  File "C:\Users\MMCCOW~1\Envs\DJANGO~1\lib\site-packages\django\template\loader_tags.py", line 53, in render
    result = self.nodelist.render(context)
  File "C:\Users\MMCCOW~1\Envs\DJANGO~1\lib\site-packages\django\template\base.py", line 937, in render
    bit = node.render_annotated(context)
  File "C:\Users\MMCCOW~1\Envs\DJANGO~1\lib\site-packages\django\template\base.py", line 904, in render_annotated
    return self.render(context)
  File "C:\Users\MMCCOW~1\Envs\DJANGO~1\lib\site-packages\django\template\defaulttags.py", line 209, in render
    nodelist.append(node.render_annotated(context))
  File "C:\Users\MMCCOW~1\Envs\DJANGO~1\lib\site-packages\django\template\base.py", line 904, in render_annotated
    return self.render(context)
  File "C:\Users\MMCCOW~1\Envs\DJANGO~1\lib\site-packages\django\template\loader_tags.py", line 53, in render
    result = self.nodelist.render(context)
  File "C:\Users\MMCCOW~1\Envs\DJANGO~1\lib\site-packages\django\template\base.py", line 937, in render
    bit = node.render_annotated(context)
  File "C:\Users\MMCCOW~1\Envs\DJANGO~1\lib\site-packages\django\template\base.py", line 904, in render_annotated
    return self.render(context)
  File "C:\Users\MMCCOW~1\Envs\DJANGO~1\lib\site-packages\django\template\defaulttags.py", line 165, in render
    values = list(values)
  File "C:\Users\MMCCOW~1\Envs\DJANGO~1\lib\site-packages\django_tables2\rows.py", line 254, in items
    column.current_value = self.get_cell(column.name)
  File "C:\Users\MMCCOW~1\Envs\DJANGO~1\lib\site-packages\django_tables2\rows.py", line 205, in get_cell
    bound_column, render_func=self._call_render, default=bound_column.default
  File "C:\Users\MMCCOW~1\Envs\DJANGO~1\lib\site-packages\django_tables2\rows.py", line 180, in _get_and_render_with
    return render_func(bound_column, value)
  File "C:\Users\MMCCOW~1\Envs\DJANGO~1\lib\site-packages\django_tables2\rows.py", line 215, in _call_render
    return bound_column.link(content, **render_kwargs) if bound_column.link else content
  File "C:\Users\MMCCOW~1\Envs\DJANGO~1\lib\site-packages\django_tables2\columns\base.py", line 155, in __call__
    attrs = self.get_attrs(**kwargs)
  File "C:\Users\MMCCOW~1\Envs\DJANGO~1\lib\site-packages\django_tables2\columns\base.py", line 150, in get_attrs
    attrs["href"] = self.compose_url(**kwargs)
  File "C:\Users\MMCCOW~1\Envs\DJANGO~1\lib\site-packages\django_tables2\columns\base.py", line 106, in compose_url
    return self.call_reverse(record=record)
  File "C:\Users\MMCCOW~1\Envs\DJANGO~1\lib\site-packages\django_tables2\columns\base.py", line 138, in call_reverse
    params["args"] = [resolve_if_accessor(a) for a in params["args"]]
  File "C:\Users\MMCCOW~1\Envs\DJANGO~1\lib\site-packages\django_tables2\columns\base.py", line 138, in <listcomp>
    params["args"] = [resolve_if_accessor(a) for a in params["args"]]
  File "C:\Users\MMCCOW~1\Envs\DJANGO~1\lib\site-packages\django_tables2\columns\base.py", line 130, in resolve_if_accessor
    return val.resolve(record) if isinstance(val, Accessor) else val
  File "C:\Users\MMCCOW~1\Envs\DJANGO~1\lib\site-packages\django_tables2\utils.py", line 363, in resolve
    key=bit, context=current_context, accessor=self
ValueError: Failed lookup for key [pk] in Records.Individual.None, when resolving the accessor _individual.pk
2019-06-26 15:39:39,179  ERROR  47252  C:\Users\MMCCOW~1\Envs\DJANGO~1\lib\site-packages\django\utils\log.py  log_response  228  Internal Server Error: /records/samples/  
Traceback (most recent call last):
  File "C:\Users\MMCCOW~1\Envs\DJANGO~1\lib\site-packages\django_tables2\utils.py", line 344, in resolve
    current = current[bit]
TypeError: 'ManyRelatedManager' object is not subscriptable

During handling of the above exception, another exception occurred:

Traceback (most recent call last):
  File "C:\Users\MMCCOW~1\Envs\DJANGO~1\lib\site-packages\django_tables2\utils.py", line 347, in resolve
    current = getattr(current, bit)
AttributeError: 'ManyRelatedManager' object has no attribute 'pk'

During handling of the above exception, another exception occurred:

Traceback (most recent call last):
  File "C:\Users\MMCCOW~1\Envs\DJANGO~1\lib\site-packages\django_tables2\utils.py", line 350, in resolve
    current = current[int(bit)]
ValueError: invalid literal for int() with base 10: 'pk'

During handling of the above exception, another exception occurred:

Traceback (most recent call last):
  File "C:\Users\MMCCOW~1\Envs\DJANGO~1\lib\site-packages\django\core\handlers\exception.py", line 34, in inner
    response = get_response(request)
  File "C:\Users\MMCCOW~1\Envs\DJANGO~1\lib\site-packages\django\core\handlers\base.py", line 156, in _get_response
    response = self.process_exception_by_middleware(e, request)
  File "C:\Users\MMCCOW~1\Envs\DJANGO~1\lib\site-packages\django\core\handlers\base.py", line 154, in _get_response
    response = response.render()
  File "C:\Users\MMCCOW~1\Envs\DJANGO~1\lib\site-packages\django\template\response.py", line 106, in render
    self.content = self.rendered_content
  File "C:\Users\MMCCOW~1\Envs\DJANGO~1\lib\site-packages\django\template\response.py", line 83, in rendered_content
    content = template.render(context, self._request)
  File "C:\Users\MMCCOW~1\Envs\DJANGO~1\lib\site-packages\django\template\backends\django.py", line 61, in render
    return self.template.render(context)
  File "C:\Users\MMCCOW~1\Envs\DJANGO~1\lib\site-packages\django\template\base.py", line 171, in render
    return self._render(context)
  File "C:\Users\MMCCOW~1\Envs\DJANGO~1\lib\site-packages\django\template\base.py", line 163, in _render
    return self.nodelist.render(context)
  File "C:\Users\MMCCOW~1\Envs\DJANGO~1\lib\site-packages\django\template\base.py", line 937, in render
    bit = node.render_annotated(context)
  File "C:\Users\MMCCOW~1\Envs\DJANGO~1\lib\site-packages\django\template\base.py", line 904, in render_annotated
    return self.render(context)
  File "C:\Users\MMCCOW~1\Envs\DJANGO~1\lib\site-packages\django\template\loader_tags.py", line 150, in render
    return compiled_parent._render(context)
  File "C:\Users\MMCCOW~1\Envs\DJANGO~1\lib\site-packages\django\template\base.py", line 163, in _render
    return self.nodelist.render(context)
  File "C:\Users\MMCCOW~1\Envs\DJANGO~1\lib\site-packages\django\template\base.py", line 937, in render
    bit = node.render_annotated(context)
  File "C:\Users\MMCCOW~1\Envs\DJANGO~1\lib\site-packages\django\template\base.py", line 904, in render_annotated
    return self.render(context)
  File "C:\Users\MMCCOW~1\Envs\DJANGO~1\lib\site-packages\django\template\loader_tags.py", line 150, in render
    return compiled_parent._render(context)
  File "C:\Users\MMCCOW~1\Envs\DJANGO~1\lib\site-packages\django\template\base.py", line 163, in _render
    return self.nodelist.render(context)
  File "C:\Users\MMCCOW~1\Envs\DJANGO~1\lib\site-packages\django\template\base.py", line 937, in render
    bit = node.render_annotated(context)
  File "C:\Users\MMCCOW~1\Envs\DJANGO~1\lib\site-packages\django\template\base.py", line 904, in render_annotated
    return self.render(context)
  File "C:\Users\MMCCOW~1\Envs\DJANGO~1\lib\site-packages\django\template\loader_tags.py", line 62, in render
    result = block.nodelist.render(context)
  File "C:\Users\MMCCOW~1\Envs\DJANGO~1\lib\site-packages\django\template\base.py", line 937, in render
    bit = node.render_annotated(context)
  File "C:\Users\MMCCOW~1\Envs\DJANGO~1\lib\site-packages\django\template\base.py", line 904, in render_annotated
    return self.render(context)
  File "C:\Users\MMCCOW~1\Envs\DJANGO~1\lib\site-packages\django_tables2\templatetags\django_tables2.py", line 170, in render
    return template.render(context={"table": table}, request=request)
  File "C:\Users\MMCCOW~1\Envs\DJANGO~1\lib\site-packages\django\template\backends\django.py", line 61, in render
    return self.template.render(context)
  File "C:\Users\MMCCOW~1\Envs\DJANGO~1\lib\site-packages\django\template\base.py", line 171, in render
    return self._render(context)
  File "C:\Users\MMCCOW~1\Envs\DJANGO~1\lib\site-packages\django\template\base.py", line 163, in _render
    return self.nodelist.render(context)
  File "C:\Users\MMCCOW~1\Envs\DJANGO~1\lib\site-packages\django\template\base.py", line 937, in render
    bit = node.render_annotated(context)
  File "C:\Users\MMCCOW~1\Envs\DJANGO~1\lib\site-packages\django\template\base.py", line 904, in render_annotated
    return self.render(context)
  File "C:\Users\MMCCOW~1\Envs\DJANGO~1\lib\site-packages\django\template\loader_tags.py", line 53, in render
    result = self.nodelist.render(context)
  File "C:\Users\MMCCOW~1\Envs\DJANGO~1\lib\site-packages\django\template\base.py", line 937, in render
    bit = node.render_annotated(context)
  File "C:\Users\MMCCOW~1\Envs\DJANGO~1\lib\site-packages\django\template\base.py", line 904, in render_annotated
    return self.render(context)
  File "C:\Users\MMCCOW~1\Envs\DJANGO~1\lib\site-packages\django\template\loader_tags.py", line 53, in render
    result = self.nodelist.render(context)
  File "C:\Users\MMCCOW~1\Envs\DJANGO~1\lib\site-packages\django\template\base.py", line 937, in render
    bit = node.render_annotated(context)
  File "C:\Users\MMCCOW~1\Envs\DJANGO~1\lib\site-packages\django\template\base.py", line 904, in render_annotated
    return self.render(context)
  File "C:\Users\MMCCOW~1\Envs\DJANGO~1\lib\site-packages\django\template\loader_tags.py", line 53, in render
    result = self.nodelist.render(context)
  File "C:\Users\MMCCOW~1\Envs\DJANGO~1\lib\site-packages\django\template\base.py", line 937, in render
    bit = node.render_annotated(context)
  File "C:\Users\MMCCOW~1\Envs\DJANGO~1\lib\site-packages\django\template\base.py", line 904, in render_annotated
    return self.render(context)
  File "C:\Users\MMCCOW~1\Envs\DJANGO~1\lib\site-packages\django\template\defaulttags.py", line 209, in render
    nodelist.append(node.render_annotated(context))
  File "C:\Users\MMCCOW~1\Envs\DJANGO~1\lib\site-packages\django\template\base.py", line 904, in render_annotated
    return self.render(context)
  File "C:\Users\MMCCOW~1\Envs\DJANGO~1\lib\site-packages\django\template\loader_tags.py", line 53, in render
    result = self.nodelist.render(context)
  File "C:\Users\MMCCOW~1\Envs\DJANGO~1\lib\site-packages\django\template\base.py", line 937, in render
    bit = node.render_annotated(context)
  File "C:\Users\MMCCOW~1\Envs\DJANGO~1\lib\site-packages\django\template\base.py", line 904, in render_annotated
    return self.render(context)
  File "C:\Users\MMCCOW~1\Envs\DJANGO~1\lib\site-packages\django\template\defaulttags.py", line 165, in render
    values = list(values)
  File "C:\Users\MMCCOW~1\Envs\DJANGO~1\lib\site-packages\django_tables2\rows.py", line 254, in items
    column.current_value = self.get_cell(column.name)
  File "C:\Users\MMCCOW~1\Envs\DJANGO~1\lib\site-packages\django_tables2\rows.py", line 205, in get_cell
    bound_column, render_func=self._call_render, default=bound_column.default
  File "C:\Users\MMCCOW~1\Envs\DJANGO~1\lib\site-packages\django_tables2\rows.py", line 180, in _get_and_render_with
    return render_func(bound_column, value)
  File "C:\Users\MMCCOW~1\Envs\DJANGO~1\lib\site-packages\django_tables2\rows.py", line 215, in _call_render
    return bound_column.link(content, **render_kwargs) if bound_column.link else content
  File "C:\Users\MMCCOW~1\Envs\DJANGO~1\lib\site-packages\django_tables2\columns\base.py", line 155, in __call__
    attrs = self.get_attrs(**kwargs)
  File "C:\Users\MMCCOW~1\Envs\DJANGO~1\lib\site-packages\django_tables2\columns\base.py", line 150, in get_attrs
    attrs["href"] = self.compose_url(**kwargs)
  File "C:\Users\MMCCOW~1\Envs\DJANGO~1\lib\site-packages\django_tables2\columns\base.py", line 106, in compose_url
    return self.call_reverse(record=record)
  File "C:\Users\MMCCOW~1\Envs\DJANGO~1\lib\site-packages\django_tables2\columns\base.py", line 138, in call_reverse
    params["args"] = [resolve_if_accessor(a) for a in params["args"]]
  File "C:\Users\MMCCOW~1\Envs\DJANGO~1\lib\site-packages\django_tables2\columns\base.py", line 138, in <listcomp>
    params["args"] = [resolve_if_accessor(a) for a in params["args"]]
  File "C:\Users\MMCCOW~1\Envs\DJANGO~1\lib\site-packages\django_tables2\columns\base.py", line 130, in resolve_if_accessor
    return val.resolve(record) if isinstance(val, Accessor) else val
  File "C:\Users\MMCCOW~1\Envs\DJANGO~1\lib\site-packages\django_tables2\utils.py", line 363, in resolve
    key=bit, context=current_context, accessor=self
ValueError: Failed lookup for key [pk] in Records.Individual.None, when resolving the accessor _individual.pk
2019-06-26 15:39:39,385  WARNING  47252  C:\Users\MMCCOW~1\Envs\DJANGO~1\lib\site-packages\django\utils\log.py  log_response  228  Not Found: /favicon.ico  
2019-06-26 15:40:08,790  WARNING  35508  C:\Users\MMCCOW~1\Envs\DJANGO~1\lib\site-packages\django\utils\log.py  log_response  228  Not Found: /favicon.ico  
2019-06-26 15:42:52,011  ERROR  27348  C:\Users\MMCCOW~1\Envs\DJANGO~1\lib\site-packages\django\utils\log.py  log_response  228  Internal Server Error: /records/samples/  
Traceback (most recent call last):
  File "C:\Users\MMCCOW~1\Envs\DJANGO~1\lib\site-packages\django\core\handlers\exception.py", line 34, in inner
    response = get_response(request)
  File "C:\Users\MMCCOW~1\Envs\DJANGO~1\lib\site-packages\django\core\handlers\base.py", line 156, in _get_response
    response = self.process_exception_by_middleware(e, request)
  File "C:\Users\MMCCOW~1\Envs\DJANGO~1\lib\site-packages\django\core\handlers\base.py", line 154, in _get_response
    response = response.render()
  File "C:\Users\MMCCOW~1\Envs\DJANGO~1\lib\site-packages\django\template\response.py", line 106, in render
    self.content = self.rendered_content
  File "C:\Users\MMCCOW~1\Envs\DJANGO~1\lib\site-packages\django\template\response.py", line 83, in rendered_content
    content = template.render(context, self._request)
  File "C:\Users\MMCCOW~1\Envs\DJANGO~1\lib\site-packages\django\template\backends\django.py", line 61, in render
    return self.template.render(context)
  File "C:\Users\MMCCOW~1\Envs\DJANGO~1\lib\site-packages\django\template\base.py", line 171, in render
    return self._render(context)
  File "C:\Users\MMCCOW~1\Envs\DJANGO~1\lib\site-packages\django\template\base.py", line 163, in _render
    return self.nodelist.render(context)
  File "C:\Users\MMCCOW~1\Envs\DJANGO~1\lib\site-packages\django\template\base.py", line 937, in render
    bit = node.render_annotated(context)
  File "C:\Users\MMCCOW~1\Envs\DJANGO~1\lib\site-packages\django\template\base.py", line 904, in render_annotated
    return self.render(context)
  File "C:\Users\MMCCOW~1\Envs\DJANGO~1\lib\site-packages\django\template\loader_tags.py", line 150, in render
    return compiled_parent._render(context)
  File "C:\Users\MMCCOW~1\Envs\DJANGO~1\lib\site-packages\django\template\base.py", line 163, in _render
    return self.nodelist.render(context)
  File "C:\Users\MMCCOW~1\Envs\DJANGO~1\lib\site-packages\django\template\base.py", line 937, in render
    bit = node.render_annotated(context)
  File "C:\Users\MMCCOW~1\Envs\DJANGO~1\lib\site-packages\django\template\base.py", line 904, in render_annotated
    return self.render(context)
  File "C:\Users\MMCCOW~1\Envs\DJANGO~1\lib\site-packages\django\template\loader_tags.py", line 150, in render
    return compiled_parent._render(context)
  File "C:\Users\MMCCOW~1\Envs\DJANGO~1\lib\site-packages\django\template\base.py", line 163, in _render
    return self.nodelist.render(context)
  File "C:\Users\MMCCOW~1\Envs\DJANGO~1\lib\site-packages\django\template\base.py", line 937, in render
    bit = node.render_annotated(context)
  File "C:\Users\MMCCOW~1\Envs\DJANGO~1\lib\site-packages\django\template\base.py", line 904, in render_annotated
    return self.render(context)
  File "C:\Users\MMCCOW~1\Envs\DJANGO~1\lib\site-packages\django\template\loader_tags.py", line 62, in render
    result = block.nodelist.render(context)
  File "C:\Users\MMCCOW~1\Envs\DJANGO~1\lib\site-packages\django\template\base.py", line 937, in render
    bit = node.render_annotated(context)
  File "C:\Users\MMCCOW~1\Envs\DJANGO~1\lib\site-packages\django\template\base.py", line 904, in render_annotated
    return self.render(context)
  File "C:\Users\MMCCOW~1\Envs\DJANGO~1\lib\site-packages\django_tables2\templatetags\django_tables2.py", line 170, in render
    return template.render(context={"table": table}, request=request)
  File "C:\Users\MMCCOW~1\Envs\DJANGO~1\lib\site-packages\django\template\backends\django.py", line 61, in render
    return self.template.render(context)
  File "C:\Users\MMCCOW~1\Envs\DJANGO~1\lib\site-packages\django\template\base.py", line 171, in render
    return self._render(context)
  File "C:\Users\MMCCOW~1\Envs\DJANGO~1\lib\site-packages\django\template\base.py", line 163, in _render
    return self.nodelist.render(context)
  File "C:\Users\MMCCOW~1\Envs\DJANGO~1\lib\site-packages\django\template\base.py", line 937, in render
    bit = node.render_annotated(context)
  File "C:\Users\MMCCOW~1\Envs\DJANGO~1\lib\site-packages\django\template\base.py", line 904, in render_annotated
    return self.render(context)
  File "C:\Users\MMCCOW~1\Envs\DJANGO~1\lib\site-packages\django\template\loader_tags.py", line 53, in render
    result = self.nodelist.render(context)
  File "C:\Users\MMCCOW~1\Envs\DJANGO~1\lib\site-packages\django\template\base.py", line 937, in render
    bit = node.render_annotated(context)
  File "C:\Users\MMCCOW~1\Envs\DJANGO~1\lib\site-packages\django\template\base.py", line 904, in render_annotated
    return self.render(context)
  File "C:\Users\MMCCOW~1\Envs\DJANGO~1\lib\site-packages\django\template\loader_tags.py", line 53, in render
    result = self.nodelist.render(context)
  File "C:\Users\MMCCOW~1\Envs\DJANGO~1\lib\site-packages\django\template\base.py", line 937, in render
    bit = node.render_annotated(context)
  File "C:\Users\MMCCOW~1\Envs\DJANGO~1\lib\site-packages\django\template\base.py", line 904, in render_annotated
    return self.render(context)
  File "C:\Users\MMCCOW~1\Envs\DJANGO~1\lib\site-packages\django\template\loader_tags.py", line 53, in render
    result = self.nodelist.render(context)
  File "C:\Users\MMCCOW~1\Envs\DJANGO~1\lib\site-packages\django\template\base.py", line 937, in render
    bit = node.render_annotated(context)
  File "C:\Users\MMCCOW~1\Envs\DJANGO~1\lib\site-packages\django\template\base.py", line 904, in render_annotated
    return self.render(context)
  File "C:\Users\MMCCOW~1\Envs\DJANGO~1\lib\site-packages\django\template\defaulttags.py", line 209, in render
    nodelist.append(node.render_annotated(context))
  File "C:\Users\MMCCOW~1\Envs\DJANGO~1\lib\site-packages\django\template\base.py", line 904, in render_annotated
    return self.render(context)
  File "C:\Users\MMCCOW~1\Envs\DJANGO~1\lib\site-packages\django\template\loader_tags.py", line 53, in render
    result = self.nodelist.render(context)
  File "C:\Users\MMCCOW~1\Envs\DJANGO~1\lib\site-packages\django\template\base.py", line 937, in render
    bit = node.render_annotated(context)
  File "C:\Users\MMCCOW~1\Envs\DJANGO~1\lib\site-packages\django\template\base.py", line 904, in render_annotated
    return self.render(context)
  File "C:\Users\MMCCOW~1\Envs\DJANGO~1\lib\site-packages\django\template\defaulttags.py", line 165, in render
    values = list(values)
  File "C:\Users\MMCCOW~1\Envs\DJANGO~1\lib\site-packages\django_tables2\rows.py", line 254, in items
    column.current_value = self.get_cell(column.name)
  File "C:\Users\MMCCOW~1\Envs\DJANGO~1\lib\site-packages\django_tables2\rows.py", line 205, in get_cell
    bound_column, render_func=self._call_render, default=bound_column.default
  File "C:\Users\MMCCOW~1\Envs\DJANGO~1\lib\site-packages\django_tables2\rows.py", line 177, in _get_and_render_with
    if value in bound_column.column.empty_values:
TypeError: 'in <string>' requires string as left operand, not ManyRelatedManager
2019-06-26 15:42:52,171  WARNING  27348  C:\Users\MMCCOW~1\Envs\DJANGO~1\lib\site-packages\django\utils\log.py  log_response  228  Not Found: /favicon.ico  
2019-06-26 15:43:08,444  ERROR  16792  C:\Users\MMCCOW~1\Envs\DJANGO~1\lib\site-packages\django\utils\log.py  log_response  228  Internal Server Error: /records/samples/  
Traceback (most recent call last):
  File "C:\Users\MMCCOW~1\Envs\DJANGO~1\lib\site-packages\django_tables2\utils.py", line 344, in resolve
    current = current[bit]
TypeError: 'ManyRelatedManager' object is not subscriptable

During handling of the above exception, another exception occurred:

Traceback (most recent call last):
  File "C:\Users\MMCCOW~1\Envs\DJANGO~1\lib\site-packages\django_tables2\utils.py", line 347, in resolve
    current = getattr(current, bit)
AttributeError: 'ManyRelatedManager' object has no attribute 'pk'

During handling of the above exception, another exception occurred:

Traceback (most recent call last):
  File "C:\Users\MMCCOW~1\Envs\DJANGO~1\lib\site-packages\django_tables2\utils.py", line 350, in resolve
    current = current[int(bit)]
ValueError: invalid literal for int() with base 10: 'pk'

During handling of the above exception, another exception occurred:

Traceback (most recent call last):
  File "C:\Users\MMCCOW~1\Envs\DJANGO~1\lib\site-packages\django\core\handlers\exception.py", line 34, in inner
    response = get_response(request)
  File "C:\Users\MMCCOW~1\Envs\DJANGO~1\lib\site-packages\django\core\handlers\base.py", line 156, in _get_response
    response = self.process_exception_by_middleware(e, request)
  File "C:\Users\MMCCOW~1\Envs\DJANGO~1\lib\site-packages\django\core\handlers\base.py", line 154, in _get_response
    response = response.render()
  File "C:\Users\MMCCOW~1\Envs\DJANGO~1\lib\site-packages\django\template\response.py", line 106, in render
    self.content = self.rendered_content
  File "C:\Users\MMCCOW~1\Envs\DJANGO~1\lib\site-packages\django\template\response.py", line 83, in rendered_content
    content = template.render(context, self._request)
  File "C:\Users\MMCCOW~1\Envs\DJANGO~1\lib\site-packages\django\template\backends\django.py", line 61, in render
    return self.template.render(context)
  File "C:\Users\MMCCOW~1\Envs\DJANGO~1\lib\site-packages\django\template\base.py", line 171, in render
    return self._render(context)
  File "C:\Users\MMCCOW~1\Envs\DJANGO~1\lib\site-packages\django\template\base.py", line 163, in _render
    return self.nodelist.render(context)
  File "C:\Users\MMCCOW~1\Envs\DJANGO~1\lib\site-packages\django\template\base.py", line 937, in render
    bit = node.render_annotated(context)
  File "C:\Users\MMCCOW~1\Envs\DJANGO~1\lib\site-packages\django\template\base.py", line 904, in render_annotated
    return self.render(context)
  File "C:\Users\MMCCOW~1\Envs\DJANGO~1\lib\site-packages\django\template\loader_tags.py", line 150, in render
    return compiled_parent._render(context)
  File "C:\Users\MMCCOW~1\Envs\DJANGO~1\lib\site-packages\django\template\base.py", line 163, in _render
    return self.nodelist.render(context)
  File "C:\Users\MMCCOW~1\Envs\DJANGO~1\lib\site-packages\django\template\base.py", line 937, in render
    bit = node.render_annotated(context)
  File "C:\Users\MMCCOW~1\Envs\DJANGO~1\lib\site-packages\django\template\base.py", line 904, in render_annotated
    return self.render(context)
  File "C:\Users\MMCCOW~1\Envs\DJANGO~1\lib\site-packages\django\template\loader_tags.py", line 150, in render
    return compiled_parent._render(context)
  File "C:\Users\MMCCOW~1\Envs\DJANGO~1\lib\site-packages\django\template\base.py", line 163, in _render
    return self.nodelist.render(context)
  File "C:\Users\MMCCOW~1\Envs\DJANGO~1\lib\site-packages\django\template\base.py", line 937, in render
    bit = node.render_annotated(context)
  File "C:\Users\MMCCOW~1\Envs\DJANGO~1\lib\site-packages\django\template\base.py", line 904, in render_annotated
    return self.render(context)
  File "C:\Users\MMCCOW~1\Envs\DJANGO~1\lib\site-packages\django\template\loader_tags.py", line 62, in render
    result = block.nodelist.render(context)
  File "C:\Users\MMCCOW~1\Envs\DJANGO~1\lib\site-packages\django\template\base.py", line 937, in render
    bit = node.render_annotated(context)
  File "C:\Users\MMCCOW~1\Envs\DJANGO~1\lib\site-packages\django\template\base.py", line 904, in render_annotated
    return self.render(context)
  File "C:\Users\MMCCOW~1\Envs\DJANGO~1\lib\site-packages\django_tables2\templatetags\django_tables2.py", line 170, in render
    return template.render(context={"table": table}, request=request)
  File "C:\Users\MMCCOW~1\Envs\DJANGO~1\lib\site-packages\django\template\backends\django.py", line 61, in render
    return self.template.render(context)
  File "C:\Users\MMCCOW~1\Envs\DJANGO~1\lib\site-packages\django\template\base.py", line 171, in render
    return self._render(context)
  File "C:\Users\MMCCOW~1\Envs\DJANGO~1\lib\site-packages\django\template\base.py", line 163, in _render
    return self.nodelist.render(context)
  File "C:\Users\MMCCOW~1\Envs\DJANGO~1\lib\site-packages\django\template\base.py", line 937, in render
    bit = node.render_annotated(context)
  File "C:\Users\MMCCOW~1\Envs\DJANGO~1\lib\site-packages\django\template\base.py", line 904, in render_annotated
    return self.render(context)
  File "C:\Users\MMCCOW~1\Envs\DJANGO~1\lib\site-packages\django\template\loader_tags.py", line 53, in render
    result = self.nodelist.render(context)
  File "C:\Users\MMCCOW~1\Envs\DJANGO~1\lib\site-packages\django\template\base.py", line 937, in render
    bit = node.render_annotated(context)
  File "C:\Users\MMCCOW~1\Envs\DJANGO~1\lib\site-packages\django\template\base.py", line 904, in render_annotated
    return self.render(context)
  File "C:\Users\MMCCOW~1\Envs\DJANGO~1\lib\site-packages\django\template\loader_tags.py", line 53, in render
    result = self.nodelist.render(context)
  File "C:\Users\MMCCOW~1\Envs\DJANGO~1\lib\site-packages\django\template\base.py", line 937, in render
    bit = node.render_annotated(context)
  File "C:\Users\MMCCOW~1\Envs\DJANGO~1\lib\site-packages\django\template\base.py", line 904, in render_annotated
    return self.render(context)
  File "C:\Users\MMCCOW~1\Envs\DJANGO~1\lib\site-packages\django\template\loader_tags.py", line 53, in render
    result = self.nodelist.render(context)
  File "C:\Users\MMCCOW~1\Envs\DJANGO~1\lib\site-packages\django\template\base.py", line 937, in render
    bit = node.render_annotated(context)
  File "C:\Users\MMCCOW~1\Envs\DJANGO~1\lib\site-packages\django\template\base.py", line 904, in render_annotated
    return self.render(context)
  File "C:\Users\MMCCOW~1\Envs\DJANGO~1\lib\site-packages\django\template\defaulttags.py", line 209, in render
    nodelist.append(node.render_annotated(context))
  File "C:\Users\MMCCOW~1\Envs\DJANGO~1\lib\site-packages\django\template\base.py", line 904, in render_annotated
    return self.render(context)
  File "C:\Users\MMCCOW~1\Envs\DJANGO~1\lib\site-packages\django\template\loader_tags.py", line 53, in render
    result = self.nodelist.render(context)
  File "C:\Users\MMCCOW~1\Envs\DJANGO~1\lib\site-packages\django\template\base.py", line 937, in render
    bit = node.render_annotated(context)
  File "C:\Users\MMCCOW~1\Envs\DJANGO~1\lib\site-packages\django\template\base.py", line 904, in render_annotated
    return self.render(context)
  File "C:\Users\MMCCOW~1\Envs\DJANGO~1\lib\site-packages\django\template\defaulttags.py", line 165, in render
    values = list(values)
  File "C:\Users\MMCCOW~1\Envs\DJANGO~1\lib\site-packages\django_tables2\rows.py", line 254, in items
    column.current_value = self.get_cell(column.name)
  File "C:\Users\MMCCOW~1\Envs\DJANGO~1\lib\site-packages\django_tables2\rows.py", line 205, in get_cell
    bound_column, render_func=self._call_render, default=bound_column.default
  File "C:\Users\MMCCOW~1\Envs\DJANGO~1\lib\site-packages\django_tables2\rows.py", line 180, in _get_and_render_with
    return render_func(bound_column, value)
  File "C:\Users\MMCCOW~1\Envs\DJANGO~1\lib\site-packages\django_tables2\rows.py", line 215, in _call_render
    return bound_column.link(content, **render_kwargs) if bound_column.link else content
  File "C:\Users\MMCCOW~1\Envs\DJANGO~1\lib\site-packages\django_tables2\columns\base.py", line 155, in __call__
    attrs = self.get_attrs(**kwargs)
  File "C:\Users\MMCCOW~1\Envs\DJANGO~1\lib\site-packages\django_tables2\columns\base.py", line 150, in get_attrs
    attrs["href"] = self.compose_url(**kwargs)
  File "C:\Users\MMCCOW~1\Envs\DJANGO~1\lib\site-packages\django_tables2\columns\base.py", line 106, in compose_url
    return self.call_reverse(record=record)
  File "C:\Users\MMCCOW~1\Envs\DJANGO~1\lib\site-packages\django_tables2\columns\base.py", line 138, in call_reverse
    params["args"] = [resolve_if_accessor(a) for a in params["args"]]
  File "C:\Users\MMCCOW~1\Envs\DJANGO~1\lib\site-packages\django_tables2\columns\base.py", line 138, in <listcomp>
    params["args"] = [resolve_if_accessor(a) for a in params["args"]]
  File "C:\Users\MMCCOW~1\Envs\DJANGO~1\lib\site-packages\django_tables2\columns\base.py", line 130, in resolve_if_accessor
    return val.resolve(record) if isinstance(val, Accessor) else val
  File "C:\Users\MMCCOW~1\Envs\DJANGO~1\lib\site-packages\django_tables2\utils.py", line 363, in resolve
    key=bit, context=current_context, accessor=self
ValueError: Failed lookup for key [pk] in Records.Individual.None, when resolving the accessor _individual.pk
2019-06-26 15:43:08,630  WARNING  16792  C:\Users\MMCCOW~1\Envs\DJANGO~1\lib\site-packages\django\utils\log.py  log_response  228  Not Found: /favicon.ico  
2019-06-26 16:20:35,189  ERROR  19376  C:\Users\MMCCOW~1\Envs\DJANGO~1\lib\site-packages\django\utils\log.py  log_response  228  Internal Server Error: /records/samples/400/  
Traceback (most recent call last):
  File "C:\Users\MMCCOW~1\Envs\DJANGO~1\lib\site-packages\django\core\handlers\exception.py", line 34, in inner
    response = get_response(request)
  File "C:\Users\MMCCOW~1\Envs\DJANGO~1\lib\site-packages\django\core\handlers\base.py", line 156, in _get_response
    response = self.process_exception_by_middleware(e, request)
  File "C:\Users\MMCCOW~1\Envs\DJANGO~1\lib\site-packages\django\core\handlers\base.py", line 154, in _get_response
    response = response.render()
  File "C:\Users\MMCCOW~1\Envs\DJANGO~1\lib\site-packages\django\template\response.py", line 106, in render
    self.content = self.rendered_content
  File "C:\Users\MMCCOW~1\Envs\DJANGO~1\lib\site-packages\django\template\response.py", line 83, in rendered_content
    content = template.render(context, self._request)
  File "C:\Users\MMCCOW~1\Envs\DJANGO~1\lib\site-packages\django\template\backends\django.py", line 61, in render
    return self.template.render(context)
  File "C:\Users\MMCCOW~1\Envs\DJANGO~1\lib\site-packages\django\template\base.py", line 171, in render
    return self._render(context)
  File "C:\Users\MMCCOW~1\Envs\DJANGO~1\lib\site-packages\django\template\base.py", line 163, in _render
    return self.nodelist.render(context)
  File "C:\Users\MMCCOW~1\Envs\DJANGO~1\lib\site-packages\django\template\base.py", line 937, in render
    bit = node.render_annotated(context)
  File "C:\Users\MMCCOW~1\Envs\DJANGO~1\lib\site-packages\django\template\base.py", line 904, in render_annotated
    return self.render(context)
  File "C:\Users\MMCCOW~1\Envs\DJANGO~1\lib\site-packages\django\template\loader_tags.py", line 150, in render
    return compiled_parent._render(context)
  File "C:\Users\MMCCOW~1\Envs\DJANGO~1\lib\site-packages\django\template\base.py", line 163, in _render
    return self.nodelist.render(context)
  File "C:\Users\MMCCOW~1\Envs\DJANGO~1\lib\site-packages\django\template\base.py", line 937, in render
    bit = node.render_annotated(context)
  File "C:\Users\MMCCOW~1\Envs\DJANGO~1\lib\site-packages\django\template\base.py", line 904, in render_annotated
    return self.render(context)
  File "C:\Users\MMCCOW~1\Envs\DJANGO~1\lib\site-packages\django\template\loader_tags.py", line 62, in render
    result = block.nodelist.render(context)
  File "C:\Users\MMCCOW~1\Envs\DJANGO~1\lib\site-packages\django\template\base.py", line 937, in render
    bit = node.render_annotated(context)
  File "C:\Users\MMCCOW~1\Envs\DJANGO~1\lib\site-packages\django\template\base.py", line 904, in render_annotated
    return self.render(context)
  File "C:\Users\MMCCOW~1\Envs\DJANGO~1\lib\site-packages\django\template\defaulttags.py", line 309, in render
    return nodelist.render(context)
  File "C:\Users\MMCCOW~1\Envs\DJANGO~1\lib\site-packages\django\template\base.py", line 937, in render
    bit = node.render_annotated(context)
  File "C:\Users\MMCCOW~1\Envs\DJANGO~1\lib\site-packages\django\template\base.py", line 904, in render_annotated
    return self.render(context)
  File "C:\Users\MMCCOW~1\Envs\DJANGO~1\lib\site-packages\django\template\defaulttags.py", line 209, in render
    nodelist.append(node.render_annotated(context))
  File "C:\Users\MMCCOW~1\Envs\DJANGO~1\lib\site-packages\django\template\base.py", line 904, in render_annotated
    return self.render(context)
  File "C:\Users\MMCCOW~1\Envs\DJANGO~1\lib\site-packages\django\template\defaulttags.py", line 442, in render
    url = reverse(view_name, args=args, kwargs=kwargs, current_app=current_app)
  File "C:\Users\MMCCOW~1\Envs\DJANGO~1\lib\site-packages\django\urls\base.py", line 90, in reverse
    return iri_to_uri(resolver._reverse_with_prefix(view, prefix, *args, **kwargs))
  File "C:\Users\MMCCOW~1\Envs\DJANGO~1\lib\site-packages\django\urls\resolvers.py", line 622, in _reverse_with_prefix
    raise NoReverseMatch(msg)
django.urls.exceptions.NoReverseMatch: Reverse for 'individuals-detail' not found. 'individuals-detail' is not a valid view function or pattern name.
2019-06-28 15:14:50,561  WARNING  24368  C:\Users\MMCCOW~1\Envs\DJANGO~1\lib\site-packages\django\utils\log.py  log_response  228  Not Found: /favicon.ico  
2019-06-28 15:21:15,006  ERROR  24368  C:\Users\MMCCOW~1\Envs\DJANGO~1\lib\site-packages\django\utils\log.py  log_response  228  Internal Server Error: /records/add/protocol/  
Traceback (most recent call last):
  File "C:\Users\MMCCOW~1\Envs\DJANGO~1\lib\site-packages\django\core\handlers\exception.py", line 34, in inner
    response = get_response(request)
  File "C:\Users\MMCCOW~1\Envs\DJANGO~1\lib\site-packages\django\core\handlers\base.py", line 126, in _get_response
    response = self.process_exception_by_middleware(e, request)
  File "C:\Users\MMCCOW~1\Envs\DJANGO~1\lib\site-packages\django\core\handlers\base.py", line 124, in _get_response
    response = wrapped_callback(request, *callback_args, **callback_kwargs)
  File "C:\Users\M McCown\SCS\DataMan\Records\views.py", line 1045, in add_protocol
    obj = File.objects.create(_file=f)
  File "C:\Users\MMCCOW~1\Envs\DJANGO~1\lib\site-packages\django\db\models\manager.py", line 82, in manager_method
    return getattr(self.get_queryset(), name)(*args, **kwargs)
  File "C:\Users\MMCCOW~1\Envs\DJANGO~1\lib\site-packages\django\db\models\query.py", line 413, in create
    obj.save(force_insert=True, using=self.db)
  File "C:\Users\MMCCOW~1\Envs\DJANGO~1\lib\site-packages\django\db\models\base.py", line 718, in save
    force_update=force_update, update_fields=update_fields)
  File "C:\Users\MMCCOW~1\Envs\DJANGO~1\lib\site-packages\django\db\models\base.py", line 748, in save_base
    updated = self._save_table(raw, cls, force_insert, force_update, using, update_fields)
  File "C:\Users\MMCCOW~1\Envs\DJANGO~1\lib\site-packages\django\db\models\base.py", line 831, in _save_table
    result = self._do_insert(cls._base_manager, using, fields, update_pk, raw)
  File "C:\Users\MMCCOW~1\Envs\DJANGO~1\lib\site-packages\django\db\models\base.py", line 869, in _do_insert
    using=using, raw=raw)
  File "C:\Users\MMCCOW~1\Envs\DJANGO~1\lib\site-packages\django\db\models\manager.py", line 82, in manager_method
    return getattr(self.get_queryset(), name)(*args, **kwargs)
  File "C:\Users\MMCCOW~1\Envs\DJANGO~1\lib\site-packages\django\db\models\query.py", line 1136, in _insert
    return query.get_compiler(using=using).execute_sql(return_id)
  File "C:\Users\MMCCOW~1\Envs\DJANGO~1\lib\site-packages\django\db\models\sql\compiler.py", line 1288, in execute_sql
    for sql, params in self.as_sql():
  File "C:\Users\MMCCOW~1\Envs\DJANGO~1\lib\site-packages\django\db\models\sql\compiler.py", line 1241, in as_sql
    for obj in self.query.objs
  File "C:\Users\MMCCOW~1\Envs\DJANGO~1\lib\site-packages\django\db\models\sql\compiler.py", line 1241, in <listcomp>
    for obj in self.query.objs
  File "C:\Users\MMCCOW~1\Envs\DJANGO~1\lib\site-packages\django\db\models\sql\compiler.py", line 1240, in <listcomp>
    [self.prepare_value(field, self.pre_save_val(field, obj)) for field in fields]
  File "C:\Users\MMCCOW~1\Envs\DJANGO~1\lib\site-packages\django\db\models\sql\compiler.py", line 1192, in pre_save_val
    return field.pre_save(obj, add=True)
  File "C:\Users\MMCCOW~1\Envs\DJANGO~1\lib\site-packages\django\db\models\fields\files.py", line 288, in pre_save
    file.save(file.name, file.file, save=False)
  File "C:\Users\MMCCOW~1\Envs\DJANGO~1\lib\site-packages\django\db\models\fields\files.py", line 87, in save
    self.name = self.storage.save(name, content, max_length=self.field.max_length)
  File "C:\Users\M McCown\SCS\DataMan\Records\models.py", line 317, in save
    tk.messagebox.showinfo('Duplicate File', "This file is already in our system and will not be uploaded again.")
  File "c:\anaconda3\Lib\tkinter\messagebox.py", line 83, in showinfo
    return _show(title, message, INFO, OK, **options)
  File "c:\anaconda3\Lib\tkinter\messagebox.py", line 72, in _show
    res = Message(**options).show()
  File "c:\anaconda3\Lib\tkinter\commondialog.py", line 39, in show
    w = Frame(self.master)
  File "c:\anaconda3\Lib\tkinter\__init__.py", line 2744, in __init__
    Widget.__init__(self, master, 'frame', cnf, {}, extra)
  File "c:\anaconda3\Lib\tkinter\__init__.py", line 2299, in __init__
    (widgetName, self._w) + extra + self._options(cnf))
RuntimeError: main thread is not in main loop
2019-06-28 15:22:53,253  ERROR  47408  C:\Users\MMCCOW~1\Envs\DJANGO~1\lib\site-packages\django\utils\log.py  log_response  228  Internal Server Error: /records/add/protocol/  
Traceback (most recent call last):
  File "C:\Users\MMCCOW~1\Envs\DJANGO~1\lib\site-packages\django\core\handlers\exception.py", line 34, in inner
    response = get_response(request)
  File "C:\Users\MMCCOW~1\Envs\DJANGO~1\lib\site-packages\django\core\handlers\base.py", line 126, in _get_response
    response = self.process_exception_by_middleware(e, request)
  File "C:\Users\MMCCOW~1\Envs\DJANGO~1\lib\site-packages\django\core\handlers\base.py", line 124, in _get_response
    response = wrapped_callback(request, *callback_args, **callback_kwargs)
  File "C:\Users\M McCown\SCS\DataMan\Records\views.py", line 1045, in add_protocol
    obj = File.objects.create(_file=f)
  File "C:\Users\MMCCOW~1\Envs\DJANGO~1\lib\site-packages\django\db\models\manager.py", line 82, in manager_method
    return getattr(self.get_queryset(), name)(*args, **kwargs)
  File "C:\Users\MMCCOW~1\Envs\DJANGO~1\lib\site-packages\django\db\models\query.py", line 413, in create
    obj.save(force_insert=True, using=self.db)
  File "C:\Users\MMCCOW~1\Envs\DJANGO~1\lib\site-packages\django\db\models\base.py", line 718, in save
    force_update=force_update, update_fields=update_fields)
  File "C:\Users\MMCCOW~1\Envs\DJANGO~1\lib\site-packages\django\db\models\base.py", line 748, in save_base
    updated = self._save_table(raw, cls, force_insert, force_update, using, update_fields)
  File "C:\Users\MMCCOW~1\Envs\DJANGO~1\lib\site-packages\django\db\models\base.py", line 831, in _save_table
    result = self._do_insert(cls._base_manager, using, fields, update_pk, raw)
  File "C:\Users\MMCCOW~1\Envs\DJANGO~1\lib\site-packages\django\db\models\base.py", line 869, in _do_insert
    using=using, raw=raw)
  File "C:\Users\MMCCOW~1\Envs\DJANGO~1\lib\site-packages\django\db\models\manager.py", line 82, in manager_method
    return getattr(self.get_queryset(), name)(*args, **kwargs)
  File "C:\Users\MMCCOW~1\Envs\DJANGO~1\lib\site-packages\django\db\models\query.py", line 1136, in _insert
    return query.get_compiler(using=using).execute_sql(return_id)
  File "C:\Users\MMCCOW~1\Envs\DJANGO~1\lib\site-packages\django\db\models\sql\compiler.py", line 1288, in execute_sql
    for sql, params in self.as_sql():
  File "C:\Users\MMCCOW~1\Envs\DJANGO~1\lib\site-packages\django\db\models\sql\compiler.py", line 1241, in as_sql
    for obj in self.query.objs
  File "C:\Users\MMCCOW~1\Envs\DJANGO~1\lib\site-packages\django\db\models\sql\compiler.py", line 1241, in <listcomp>
    for obj in self.query.objs
  File "C:\Users\MMCCOW~1\Envs\DJANGO~1\lib\site-packages\django\db\models\sql\compiler.py", line 1240, in <listcomp>
    [self.prepare_value(field, self.pre_save_val(field, obj)) for field in fields]
  File "C:\Users\MMCCOW~1\Envs\DJANGO~1\lib\site-packages\django\db\models\sql\compiler.py", line 1192, in pre_save_val
    return field.pre_save(obj, add=True)
  File "C:\Users\MMCCOW~1\Envs\DJANGO~1\lib\site-packages\django\db\models\fields\files.py", line 288, in pre_save
    file.save(file.name, file.file, save=False)
  File "C:\Users\MMCCOW~1\Envs\DJANGO~1\lib\site-packages\django\db\models\fields\files.py", line 87, in save
    self.name = self.storage.save(name, content, max_length=self.field.max_length)
  File "C:\Users\M McCown\SCS\DataMan\Records\models.py", line 321, in save
    msg_box = tk.messagebox.askquestion ('Warning: Duplicate Name','A file exists by this name, but is not the same file. Change name or cancel upload?',icon = 'warning')
  File "c:\anaconda3\Lib\tkinter\messagebox.py", line 95, in askquestion
    return _show(title, message, QUESTION, YESNO, **options)
  File "c:\anaconda3\Lib\tkinter\messagebox.py", line 72, in _show
    res = Message(**options).show()
  File "c:\anaconda3\Lib\tkinter\commondialog.py", line 39, in show
    w = Frame(self.master)
  File "c:\anaconda3\Lib\tkinter\__init__.py", line 2744, in __init__
    Widget.__init__(self, master, 'frame', cnf, {}, extra)
  File "c:\anaconda3\Lib\tkinter\__init__.py", line 2299, in __init__
    (widgetName, self._w) + extra + self._options(cnf))
RuntimeError: main thread is not in main loop
2019-06-28 15:27:38,488  ERROR  47408  C:\Users\MMCCOW~1\Envs\DJANGO~1\lib\site-packages\django\utils\log.py  log_response  228  Internal Server Error: /records/add/protocol/  
Traceback (most recent call last):
  File "C:\Users\MMCCOW~1\Envs\DJANGO~1\lib\site-packages\django\core\handlers\exception.py", line 34, in inner
    response = get_response(request)
  File "C:\Users\MMCCOW~1\Envs\DJANGO~1\lib\site-packages\django\core\handlers\base.py", line 126, in _get_response
    response = self.process_exception_by_middleware(e, request)
  File "C:\Users\MMCCOW~1\Envs\DJANGO~1\lib\site-packages\django\core\handlers\base.py", line 124, in _get_response
    response = wrapped_callback(request, *callback_args, **callback_kwargs)
  File "C:\Users\M McCown\SCS\DataMan\Records\views.py", line 1045, in add_protocol
    obj = File.objects.create(_file=f)
  File "C:\Users\MMCCOW~1\Envs\DJANGO~1\lib\site-packages\django\db\models\manager.py", line 82, in manager_method
    return getattr(self.get_queryset(), name)(*args, **kwargs)
  File "C:\Users\MMCCOW~1\Envs\DJANGO~1\lib\site-packages\django\db\models\query.py", line 413, in create
    obj.save(force_insert=True, using=self.db)
  File "C:\Users\MMCCOW~1\Envs\DJANGO~1\lib\site-packages\django\db\models\base.py", line 718, in save
    force_update=force_update, update_fields=update_fields)
  File "C:\Users\MMCCOW~1\Envs\DJANGO~1\lib\site-packages\django\db\models\base.py", line 748, in save_base
    updated = self._save_table(raw, cls, force_insert, force_update, using, update_fields)
  File "C:\Users\MMCCOW~1\Envs\DJANGO~1\lib\site-packages\django\db\models\base.py", line 831, in _save_table
    result = self._do_insert(cls._base_manager, using, fields, update_pk, raw)
  File "C:\Users\MMCCOW~1\Envs\DJANGO~1\lib\site-packages\django\db\models\base.py", line 869, in _do_insert
    using=using, raw=raw)
  File "C:\Users\MMCCOW~1\Envs\DJANGO~1\lib\site-packages\django\db\models\manager.py", line 82, in manager_method
    return getattr(self.get_queryset(), name)(*args, **kwargs)
  File "C:\Users\MMCCOW~1\Envs\DJANGO~1\lib\site-packages\django\db\models\query.py", line 1136, in _insert
    return query.get_compiler(using=using).execute_sql(return_id)
  File "C:\Users\MMCCOW~1\Envs\DJANGO~1\lib\site-packages\django\db\models\sql\compiler.py", line 1288, in execute_sql
    for sql, params in self.as_sql():
  File "C:\Users\MMCCOW~1\Envs\DJANGO~1\lib\site-packages\django\db\models\sql\compiler.py", line 1241, in as_sql
    for obj in self.query.objs
  File "C:\Users\MMCCOW~1\Envs\DJANGO~1\lib\site-packages\django\db\models\sql\compiler.py", line 1241, in <listcomp>
    for obj in self.query.objs
  File "C:\Users\MMCCOW~1\Envs\DJANGO~1\lib\site-packages\django\db\models\sql\compiler.py", line 1240, in <listcomp>
    [self.prepare_value(field, self.pre_save_val(field, obj)) for field in fields]
  File "C:\Users\MMCCOW~1\Envs\DJANGO~1\lib\site-packages\django\db\models\sql\compiler.py", line 1192, in pre_save_val
    return field.pre_save(obj, add=True)
  File "C:\Users\MMCCOW~1\Envs\DJANGO~1\lib\site-packages\django\db\models\fields\files.py", line 288, in pre_save
    file.save(file.name, file.file, save=False)
  File "C:\Users\MMCCOW~1\Envs\DJANGO~1\lib\site-packages\django\db\models\fields\files.py", line 87, in save
    self.name = self.storage.save(name, content, max_length=self.field.max_length)
  File "C:\Users\M McCown\SCS\DataMan\Records\models.py", line 321, in save
    msg_box = tk.messagebox.askquestion ('Warning: Duplicate Name','A file exists by this name, but is not the same file. Change name or cancel upload?',icon = 'warning')
  File "c:\anaconda3\Lib\tkinter\messagebox.py", line 95, in askquestion
    return _show(title, message, QUESTION, YESNO, **options)
  File "c:\anaconda3\Lib\tkinter\messagebox.py", line 72, in _show
    res = Message(**options).show()
  File "c:\anaconda3\Lib\tkinter\commondialog.py", line 39, in show
    w = Frame(self.master)
  File "c:\anaconda3\Lib\tkinter\__init__.py", line 2744, in __init__
    Widget.__init__(self, master, 'frame', cnf, {}, extra)
  File "c:\anaconda3\Lib\tkinter\__init__.py", line 2299, in __init__
    (widgetName, self._w) + extra + self._options(cnf))
RuntimeError: main thread is not in main loop
2019-06-28 15:29:22,769  ERROR  13516  C:\Users\MMCCOW~1\Envs\DJANGO~1\lib\site-packages\django\utils\log.py  log_response  228  Internal Server Error: /records/add/protocol/  
Traceback (most recent call last):
  File "C:\Users\MMCCOW~1\Envs\DJANGO~1\lib\site-packages\django\core\handlers\exception.py", line 34, in inner
    response = get_response(request)
  File "C:\Users\MMCCOW~1\Envs\DJANGO~1\lib\site-packages\django\core\handlers\base.py", line 126, in _get_response
    response = self.process_exception_by_middleware(e, request)
  File "C:\Users\MMCCOW~1\Envs\DJANGO~1\lib\site-packages\django\core\handlers\base.py", line 124, in _get_response
    response = wrapped_callback(request, *callback_args, **callback_kwargs)
  File "C:\Users\M McCown\SCS\DataMan\Records\views.py", line 1045, in add_protocol
    obj = File.objects.create(_file=f)
  File "C:\Users\MMCCOW~1\Envs\DJANGO~1\lib\site-packages\django\db\models\manager.py", line 82, in manager_method
    return getattr(self.get_queryset(), name)(*args, **kwargs)
  File "C:\Users\MMCCOW~1\Envs\DJANGO~1\lib\site-packages\django\db\models\query.py", line 413, in create
    obj.save(force_insert=True, using=self.db)
  File "C:\Users\MMCCOW~1\Envs\DJANGO~1\lib\site-packages\django\db\models\base.py", line 718, in save
    force_update=force_update, update_fields=update_fields)
  File "C:\Users\MMCCOW~1\Envs\DJANGO~1\lib\site-packages\django\db\models\base.py", line 748, in save_base
    updated = self._save_table(raw, cls, force_insert, force_update, using, update_fields)
  File "C:\Users\MMCCOW~1\Envs\DJANGO~1\lib\site-packages\django\db\models\base.py", line 831, in _save_table
    result = self._do_insert(cls._base_manager, using, fields, update_pk, raw)
  File "C:\Users\MMCCOW~1\Envs\DJANGO~1\lib\site-packages\django\db\models\base.py", line 869, in _do_insert
    using=using, raw=raw)
  File "C:\Users\MMCCOW~1\Envs\DJANGO~1\lib\site-packages\django\db\models\manager.py", line 82, in manager_method
    return getattr(self.get_queryset(), name)(*args, **kwargs)
  File "C:\Users\MMCCOW~1\Envs\DJANGO~1\lib\site-packages\django\db\models\query.py", line 1136, in _insert
    return query.get_compiler(using=using).execute_sql(return_id)
  File "C:\Users\MMCCOW~1\Envs\DJANGO~1\lib\site-packages\django\db\models\sql\compiler.py", line 1288, in execute_sql
    for sql, params in self.as_sql():
  File "C:\Users\MMCCOW~1\Envs\DJANGO~1\lib\site-packages\django\db\models\sql\compiler.py", line 1241, in as_sql
    for obj in self.query.objs
  File "C:\Users\MMCCOW~1\Envs\DJANGO~1\lib\site-packages\django\db\models\sql\compiler.py", line 1241, in <listcomp>
    for obj in self.query.objs
  File "C:\Users\MMCCOW~1\Envs\DJANGO~1\lib\site-packages\django\db\models\sql\compiler.py", line 1240, in <listcomp>
    [self.prepare_value(field, self.pre_save_val(field, obj)) for field in fields]
  File "C:\Users\MMCCOW~1\Envs\DJANGO~1\lib\site-packages\django\db\models\sql\compiler.py", line 1192, in pre_save_val
    return field.pre_save(obj, add=True)
  File "C:\Users\MMCCOW~1\Envs\DJANGO~1\lib\site-packages\django\db\models\fields\files.py", line 288, in pre_save
    file.save(file.name, file.file, save=False)
  File "C:\Users\MMCCOW~1\Envs\DJANGO~1\lib\site-packages\django\db\models\fields\files.py", line 87, in save
    self.name = self.storage.save(name, content, max_length=self.field.max_length)
  File "C:\Users\M McCown\SCS\DataMan\Records\models.py", line 323, in save
    if msg_box == 'yes': print ("Yes was selected.")
NameError: name 'msg_box' is not defined
2019-06-28 15:31:11,839  ERROR  2712  C:\Users\MMCCOW~1\Envs\DJANGO~1\lib\site-packages\django\utils\log.py  log_response  228  Internal Server Error: /records/add/protocol/  
Traceback (most recent call last):
  File "C:\Users\MMCCOW~1\Envs\DJANGO~1\lib\site-packages\django\core\handlers\exception.py", line 34, in inner
    response = get_response(request)
  File "C:\Users\MMCCOW~1\Envs\DJANGO~1\lib\site-packages\django\core\handlers\base.py", line 126, in _get_response
    response = self.process_exception_by_middleware(e, request)
  File "C:\Users\MMCCOW~1\Envs\DJANGO~1\lib\site-packages\django\core\handlers\base.py", line 124, in _get_response
    response = wrapped_callback(request, *callback_args, **callback_kwargs)
  File "C:\Users\M McCown\SCS\DataMan\Records\views.py", line 1045, in add_protocol
    obj = File.objects.create(_file=f)
  File "C:\Users\MMCCOW~1\Envs\DJANGO~1\lib\site-packages\django\db\models\manager.py", line 82, in manager_method
    return getattr(self.get_queryset(), name)(*args, **kwargs)
  File "C:\Users\MMCCOW~1\Envs\DJANGO~1\lib\site-packages\django\db\models\query.py", line 413, in create
    obj.save(force_insert=True, using=self.db)
  File "C:\Users\MMCCOW~1\Envs\DJANGO~1\lib\site-packages\django\db\models\base.py", line 718, in save
    force_update=force_update, update_fields=update_fields)
  File "C:\Users\MMCCOW~1\Envs\DJANGO~1\lib\site-packages\django\db\models\base.py", line 748, in save_base
    updated = self._save_table(raw, cls, force_insert, force_update, using, update_fields)
  File "C:\Users\MMCCOW~1\Envs\DJANGO~1\lib\site-packages\django\db\models\base.py", line 831, in _save_table
    result = self._do_insert(cls._base_manager, using, fields, update_pk, raw)
  File "C:\Users\MMCCOW~1\Envs\DJANGO~1\lib\site-packages\django\db\models\base.py", line 869, in _do_insert
    using=using, raw=raw)
  File "C:\Users\MMCCOW~1\Envs\DJANGO~1\lib\site-packages\django\db\models\manager.py", line 82, in manager_method
    return getattr(self.get_queryset(), name)(*args, **kwargs)
  File "C:\Users\MMCCOW~1\Envs\DJANGO~1\lib\site-packages\django\db\models\query.py", line 1136, in _insert
    return query.get_compiler(using=using).execute_sql(return_id)
  File "C:\Users\MMCCOW~1\Envs\DJANGO~1\lib\site-packages\django\db\models\sql\compiler.py", line 1288, in execute_sql
    for sql, params in self.as_sql():
  File "C:\Users\MMCCOW~1\Envs\DJANGO~1\lib\site-packages\django\db\models\sql\compiler.py", line 1241, in as_sql
    for obj in self.query.objs
  File "C:\Users\MMCCOW~1\Envs\DJANGO~1\lib\site-packages\django\db\models\sql\compiler.py", line 1241, in <listcomp>
    for obj in self.query.objs
  File "C:\Users\MMCCOW~1\Envs\DJANGO~1\lib\site-packages\django\db\models\sql\compiler.py", line 1240, in <listcomp>
    [self.prepare_value(field, self.pre_save_val(field, obj)) for field in fields]
  File "C:\Users\MMCCOW~1\Envs\DJANGO~1\lib\site-packages\django\db\models\sql\compiler.py", line 1192, in pre_save_val
    return field.pre_save(obj, add=True)
  File "C:\Users\MMCCOW~1\Envs\DJANGO~1\lib\site-packages\django\db\models\fields\files.py", line 288, in pre_save
    file.save(file.name, file.file, save=False)
  File "C:\Users\MMCCOW~1\Envs\DJANGO~1\lib\site-packages\django\db\models\fields\files.py", line 87, in save
    self.name = self.storage.save(name, content, max_length=self.field.max_length)
  File "C:\Users\M McCown\SCS\DataMan\Records\models.py", line 321, in save
    msg_box = tk.messagebox.askquestion ('Warning: Duplicate Name','A file exists by this name, but is not the same file. Change name or cancel upload?',icon = 'warning')
  File "c:\anaconda3\Lib\tkinter\messagebox.py", line 95, in askquestion
    return _show(title, message, QUESTION, YESNO, **options)
  File "c:\anaconda3\Lib\tkinter\messagebox.py", line 72, in _show
    res = Message(**options).show()
  File "c:\anaconda3\Lib\tkinter\commondialog.py", line 39, in show
    w = Frame(self.master)
  File "c:\anaconda3\Lib\tkinter\__init__.py", line 2744, in __init__
    Widget.__init__(self, master, 'frame', cnf, {}, extra)
  File "c:\anaconda3\Lib\tkinter\__init__.py", line 2299, in __init__
    (widgetName, self._w) + extra + self._options(cnf))
RuntimeError: main thread is not in main loop
2019-07-16 15:50:33,106  WARNING  18120  C:\Users\MMCCOW~1\Envs\DJANGO~1\lib\site-packages\django\utils\log.py  log_response  228  Not Found: /favicon.ico  
